<robot
  name="mover">
  <link
    name="base_link">
    <inertial>
      <origin
        xyz="0 0 0"
        rpy="0 0 0" />
      <mass
        value="50" />
      <inertia
        ixx="0.5503"
        ixy="-8.9614E-06"
        ixz="0.012965"
        iyy="0.86245"
        iyz="-4.7241E-06"
        izz="1.1183" />
    </inertial>
    <visual>
      <origin
        xyz="0 0 0"
        rpy="0 0 0" />
      <geometry>
        <mesh
          filename="package://allians/meshes/base_link.STL" />
      </geometry>
      <material
        name="">
        <color
          rgba="1 1 1 1" />
      </material>
    </visual>
    <collision>
      <origin
        xyz="0 0 0"
        rpy="0 0 0" />
      <geometry>
        <mesh
          filename="package://allians/meshes/base_link.STL" />
      </geometry>
    </collision>

    <visual>
      <origin
        xyz="-0.305 0.217 0.0625"
        rpy="0 0 0" />
      <geometry>
        <mesh
          filename="package://final/meshes/left_back.STL" />
      </geometry>
      <material
        name="">
        <color
          rgba="1 1 1 1" />
      </material>
    </visual>
    <collision>
      <origin
        xyz="-0.305 0.217 0.0625"
        rpy="0 0 0" />
      <geometry>
        <mesh
          filename="package://final/meshes/left_back.STL" />
      </geometry>
    </collision>

    <visual>
      <origin
        xyz="-0.305 0.217 0.0625"
        rpy="0 0 0" />
      <geometry>
        <mesh
          filename="package://final/meshes/left_back.STL" />
      </geometry>
      <material
        name="">
        <color
          rgba="1 1 1 1" />
      </material>
    </visual>
    <collision>
      <origin
        xyz="-0.305 0.217 0.0625"
        rpy="0 0 0" />
      <geometry>
        <mesh
          filename="package://final/meshes/left_back.STL" />
      </geometry>
    </collision>

    <visual>
      <origin
        xyz="0.305 0.217 0.0625"
        rpy="0 0 0" />
      <geometry>
        <mesh
          filename="package://final/meshes/left_back.STL" />
      </geometry>
      <material
        name="">
        <color
          rgba="1 1 1 1" />
      </material>
    </visual>
    <collision>
      <origin
        xyz="0.305 0.217 0.0625"
        rpy="0 0 0" />
      <geometry>
        <mesh
          filename="package://final/meshes/left_back.STL" />
      </geometry>
    </collision>

    <visual>
      <origin
        xyz="0.305 -0.217 0.0625"
        rpy="0 0 0" />
      <geometry>
        <mesh
          filename="package://final/meshes/left_back.STL" />
      </geometry>
      <material
        name="">
        <color
          rgba="1 1 1 1" />
      </material>
    </visual>
    <collision>
      <origin
        xyz="0.305 -0.217 0.0625"
        rpy="0 0 0" />
      <geometry>
        <mesh
          filename="package://final/meshes/left_back.STL" />
      </geometry>
    </collision>

    <visual>
      <origin
        xyz="-0.305 -0.217 0.0625"
        rpy="0 0 0" />
      <geometry>
        <mesh
          filename="package://final/meshes/left_back.STL" />
      </geometry>
      <material
        name="">
        <color
          rgba="1 1 1 1" />
      </material>
    </visual>
    <collision>
      <origin
        xyz="-0.305 -0.217 0.0625"
        rpy="0 0 0" />
      <geometry>
        <mesh
          filename="package://final/meshes/left_back.STL" />
      </geometry>
    </collision>

  </link>
  <link
    name="laser">
    <inertial>
      <origin
        xyz="0.42598 -2.1028E-05 0.16617"
        rpy="0 0 0" />
      <mass
        value="0.3" />
      <inertia
        ixx="0.00013913"
        ixy="2.7365E-08"
        ixz="2.4265E-06"
        iyy="0.00013673"
        iyz="-4.5772E-08"
        izz="9.1699E-05" />
    </inertial>
    <visual>
      <origin
        xyz="0 0 0"
        rpy="0 0 0" />
      <geometry>
        <mesh
          filename="package://allians/meshes/laser.STL" />
      </geometry>
      <material
        name="">
        <color
          rgba="1 1 1 1" />
      </material>
    </visual>
    <collision>
      <origin
        xyz="0 0 0"
        rpy="0 0 0" />
      <geometry>
        <mesh
          filename="package://allians/meshes/laser.STL" />
      </geometry>
    </collision>
  </link>
  <joint
    name="laser"
    type="fixed">
    <origin
      xyz="0 0 0.15"
      rpy="0 0 0" />
    <parent
      link="base_link" />
    <child
      link="laser" />
    <axis
      xyz="0 0 0" />
  </joint>
  <link
    name="right_wheel">
    <inertial>
      <origin
        xyz="8.3554E-10 -0.241 2.8445E-08"
        rpy="0 0 0" />
      <mass
        value="2.5" />
      <inertia
        ixx="0.016449"
        ixy="2.6288E-10"
        ixz="4.1984E-17"
        iyy="0.027311"
        iyz="8.9495E-09"
        izz="0.016449" />
    </inertial>
    <visual>
      <origin
        xyz="0 0 0"
        rpy="0 0 0" />
      <geometry>
        <mesh
          filename="package://allians/meshes/right_wheel.STL" />
      </geometry>
      <material
        name="">
        <color
          rgba="0.29804 0.29804 0.29804 1" />
      </material>
    </visual>
    <collision>
      <origin
        xyz="0 0 0"
        rpy="0 0 0" />
      <geometry>
        <mesh
          filename="package://allians/meshes/right_wheel.STL" />
      </geometry>
    </collision>
  </link>
  <joint
    name="right_wheel"
    type="continuous">
    <origin
      xyz="0 0 0.15"
      rpy="0 0 0" />
    <parent
      link="base_link" />
    <child
      link="right_wheel" />
    <axis
      xyz="0 1 0" />
  </joint>
  <link
    name="left_wheel">
    <inertial>
      <origin
        xyz="7.8515E-11 0.241 2.6729E-09"
        rpy="0 0 0" />
      <mass
        value="2.5" />
      <inertia
        ixx="0.016449"
        ixy="3.4632E-10"
        ixz="-1.5491E-17"
        iyy="0.027311"
        iyz="1.179E-08"
        izz="0.016449" />
    </inertial>
    <visual>
      <origin
        xyz="0 0 0"
        rpy="0 0 0" />
      <geometry>
        <mesh
          filename="package://allians/meshes/left_wheel.STL" />
      </geometry>
      <material
        name="">
        <color
          rgba="0.29804 0.29804 0.29804 1" />
      </material>
    </visual>
    <collision>
      <origin
        xyz="0 0 0"
        rpy="0 0 0" />
      <geometry>
        <mesh
          filename="package://allians/meshes/left_wheel.STL" />
      </geometry>
    </collision>
  </link>
  <joint
    name="left_wheel"
    type="continuous">
    <origin
      xyz="0 0 0.15"
      rpy="0 0 0" />
    <parent
      link="base_link" />
    <child
      link="left_wheel" />
    <axis
      xyz="0 1 0" />
  </joint>
</robot>
